[2024-09-11T02:25:16.393+0000] {local_task_job_runner.py:123} INFO - ::group::Pre task execution logs
[2024-09-11T02:25:16.412+0000] {taskinstance.py:2603} INFO - Dependencies all met for dep_context=non-requeueable deps ti=<TaskInstance: start_mongo_dag01.extract_from_mongo manual__2024-09-11T02:25:15.899644+00:00 [queued]>
[2024-09-11T02:25:16.424+0000] {taskinstance.py:2603} INFO - Dependencies all met for dep_context=requeueable deps ti=<TaskInstance: start_mongo_dag01.extract_from_mongo manual__2024-09-11T02:25:15.899644+00:00 [queued]>
[2024-09-11T02:25:16.425+0000] {taskinstance.py:2856} INFO - Starting attempt 1 of 2
[2024-09-11T02:25:16.441+0000] {taskinstance.py:2879} INFO - Executing <Task(PythonOperator): extract_from_mongo> on 2024-09-11 02:25:15.899644+00:00
[2024-09-11T02:25:16.450+0000] {logging_mixin.py:190} WARNING - /home/***/.local/lib/python3.12/site-packages/***/task/task_runner/standard_task_runner.py:70 DeprecationWarning: This process (pid=694) is multi-threaded, use of fork() may lead to deadlocks in the child.
[2024-09-11T02:25:16.451+0000] {standard_task_runner.py:72} INFO - Started process 695 to run task
[2024-09-11T02:25:16.450+0000] {standard_task_runner.py:104} INFO - Running: ['***', 'tasks', 'run', 'start_mongo_dag01', 'extract_from_mongo', 'manual__2024-09-11T02:25:15.899644+00:00', '--job-id', '12', '--raw', '--subdir', 'DAGS_FOLDER/mongodb-pipeline.py', '--cfg-path', '/tmp/tmpcky6o1_a']
[2024-09-11T02:25:16.452+0000] {standard_task_runner.py:105} INFO - Job 12: Subtask extract_from_mongo
[2024-09-11T02:25:16.496+0000] {task_command.py:467} INFO - Running <TaskInstance: start_mongo_dag01.extract_from_mongo manual__2024-09-11T02:25:15.899644+00:00 [running]> on host dca6f81c3bd4
[2024-09-11T02:25:16.709+0000] {taskinstance.py:3122} INFO - Exporting env vars: AIRFLOW_CTX_DAG_OWNER='***' AIRFLOW_CTX_DAG_ID='start_mongo_dag01' AIRFLOW_CTX_TASK_ID='extract_from_mongo' AIRFLOW_CTX_EXECUTION_DATE='2024-09-11T02:25:15.899644+00:00' AIRFLOW_CTX_TRY_NUMBER='1' AIRFLOW_CTX_DAG_RUN_ID='manual__2024-09-11T02:25:15.899644+00:00'
[2024-09-11T02:25:16.709+0000] {taskinstance.py:731} INFO - ::endgroup::
[2024-09-11T02:25:16.744+0000] {taskinstance.py:3301} ERROR - Task failed with exception
Traceback (most recent call last):
  File "/home/airflow/.local/lib/python3.12/site-packages/airflow/models/taskinstance.py", line 767, in _execute_task
    result = _execute_callable(context=context, **execute_callable_kwargs)
             ^^^^^^^^^^^^^^^^^^^^^^^^^^^^^^^^^^^^^^^^^^^^^^^^^^^^^^^^^^^^^
  File "/home/airflow/.local/lib/python3.12/site-packages/airflow/models/taskinstance.py", line 733, in _execute_callable
    return ExecutionCallableRunner(
           ^^^^^^^^^^^^^^^^^^^^^^^^
  File "/home/airflow/.local/lib/python3.12/site-packages/airflow/utils/operator_helpers.py", line 252, in run
    return self.func(*args, **kwargs)
           ^^^^^^^^^^^^^^^^^^^^^^^^^^
  File "/home/airflow/.local/lib/python3.12/site-packages/airflow/models/baseoperator.py", line 406, in wrapper
    return func(self, *args, **kwargs)
           ^^^^^^^^^^^^^^^^^^^^^^^^^^^
  File "/home/airflow/.local/lib/python3.12/site-packages/airflow/operators/python.py", line 238, in execute
    return_value = self.execute_callable()
                   ^^^^^^^^^^^^^^^^^^^^^^^
  File "/home/airflow/.local/lib/python3.12/site-packages/airflow/operators/python.py", line 256, in execute_callable
    return runner.run(*self.op_args, **self.op_kwargs)
           ^^^^^^^^^^^^^^^^^^^^^^^^^^^^^^^^^^^^^^^^^^^
  File "/home/airflow/.local/lib/python3.12/site-packages/airflow/utils/operator_helpers.py", line 252, in run
    return self.func(*args, **kwargs)
           ^^^^^^^^^^^^^^^^^^^^^^^^^^
  File "/opt/airflow/dags/mongodb-pipeline.py", line 16, in extract_from_mongo
    for document in documents:
                    ^^^^^^^^^
  File "/home/airflow/.local/lib/python3.12/site-packages/pymongo/cursor.py", line 1243, in next
    if len(self.__data) or self._refresh():
                           ^^^^^^^^^^^^^^^
  File "/home/airflow/.local/lib/python3.12/site-packages/pymongo/cursor.py", line 1160, in _refresh
    self.__send_message(q)
  File "/home/airflow/.local/lib/python3.12/site-packages/pymongo/cursor.py", line 1039, in __send_message
    response = client._run_operation(
               ^^^^^^^^^^^^^^^^^^^^^^
  File "/home/airflow/.local/lib/python3.12/site-packages/pymongo/_csot.py", line 108, in csot_wrapper
    return func(self, *args, **kwargs)
           ^^^^^^^^^^^^^^^^^^^^^^^^^^^
  File "/home/airflow/.local/lib/python3.12/site-packages/pymongo/mongo_client.py", line 1431, in _run_operation
    return self._retryable_read(
           ^^^^^^^^^^^^^^^^^^^^^
  File "/home/airflow/.local/lib/python3.12/site-packages/pymongo/mongo_client.py", line 1540, in _retryable_read
    return self._retry_internal(
           ^^^^^^^^^^^^^^^^^^^^^
  File "/home/airflow/.local/lib/python3.12/site-packages/pymongo/_csot.py", line 108, in csot_wrapper
    return func(self, *args, **kwargs)
           ^^^^^^^^^^^^^^^^^^^^^^^^^^^
  File "/home/airflow/.local/lib/python3.12/site-packages/pymongo/mongo_client.py", line 1507, in _retry_internal
    ).run()
      ^^^^^
  File "/home/airflow/.local/lib/python3.12/site-packages/pymongo/mongo_client.py", line 2353, in run
    return self._read() if self._is_read else self._write()
           ^^^^^^^^^^^^
  File "/home/airflow/.local/lib/python3.12/site-packages/pymongo/mongo_client.py", line 2485, in _read
    with self._client._conn_from_server(self._read_pref, self._server, self._session) as (
  File "/usr/local/lib/python3.12/contextlib.py", line 137, in __enter__
    return next(self.gen)
           ^^^^^^^^^^^^^^
  File "/home/airflow/.local/lib/python3.12/site-packages/pymongo/mongo_client.py", line 1357, in _conn_from_server
    with self._checkout(server, session) as conn:
  File "/usr/local/lib/python3.12/contextlib.py", line 137, in __enter__
    return next(self.gen)
           ^^^^^^^^^^^^^^
  File "/home/airflow/.local/lib/python3.12/site-packages/pymongo/mongo_client.py", line 1266, in _checkout
    with server.checkout(handler=err_handler) as conn:
  File "/usr/local/lib/python3.12/contextlib.py", line 137, in __enter__
    return next(self.gen)
           ^^^^^^^^^^^^^^
  File "/home/airflow/.local/lib/python3.12/site-packages/pymongo/pool.py", line 1767, in checkout
    conn = self._get_conn(checkout_started_time, handler=handler)
           ^^^^^^^^^^^^^^^^^^^^^^^^^^^^^^^^^^^^^^^^^^^^^^^^^^^^^^
  File "/home/airflow/.local/lib/python3.12/site-packages/pymongo/pool.py", line 1926, in _get_conn
    conn = self.connect(handler=handler)
           ^^^^^^^^^^^^^^^^^^^^^^^^^^^^^
  File "/home/airflow/.local/lib/python3.12/site-packages/pymongo/pool.py", line 1729, in connect
    conn.authenticate()
  File "/home/airflow/.local/lib/python3.12/site-packages/pymongo/pool.py", line 1099, in authenticate
    auth.authenticate(creds, self, reauthenticate=reauthenticate)
  File "/home/airflow/.local/lib/python3.12/site-packages/pymongo/auth.py", line 656, in authenticate
    auth_func(credentials, conn)
  File "/home/airflow/.local/lib/python3.12/site-packages/pymongo/auth.py", line 560, in _authenticate_default
    return _authenticate_scram(credentials, conn, "SCRAM-SHA-1")
           ^^^^^^^^^^^^^^^^^^^^^^^^^^^^^^^^^^^^^^^^^^^^^^^^^^^^^
  File "/home/airflow/.local/lib/python3.12/site-packages/pymongo/auth.py", line 299, in _authenticate_scram
    res = conn.command(source, cmd)
          ^^^^^^^^^^^^^^^^^^^^^^^^^
  File "/home/airflow/.local/lib/python3.12/site-packages/pymongo/helpers.py", line 342, in inner
    return func(*args, **kwargs)
           ^^^^^^^^^^^^^^^^^^^^^
  File "/home/airflow/.local/lib/python3.12/site-packages/pymongo/pool.py", line 989, in command
    return command(
           ^^^^^^^^
  File "/home/airflow/.local/lib/python3.12/site-packages/pymongo/network.py", line 212, in command
    helpers._check_command_response(
  File "/home/airflow/.local/lib/python3.12/site-packages/pymongo/helpers.py", line 248, in _check_command_response
    raise OperationFailure(errmsg, code, response, max_wire_version)
pymongo.errors.OperationFailure: Authentication failed., full error: {'ok': 0.0, 'errmsg': 'Authentication failed.', 'code': 18, 'codeName': 'AuthenticationFailed'}
[2024-09-11T02:25:16.757+0000] {taskinstance.py:1225} INFO - Marking task as UP_FOR_RETRY. dag_id=start_mongo_dag01, task_id=extract_from_mongo, run_id=manual__2024-09-11T02:25:15.899644+00:00, execution_date=20240911T022515, start_date=20240911T022516, end_date=20240911T022516
[2024-09-11T02:25:16.769+0000] {taskinstance.py:340} INFO - ::group::Post task execution logs
[2024-09-11T02:25:16.770+0000] {standard_task_runner.py:124} ERROR - Failed to execute job 12 for task extract_from_mongo (Authentication failed., full error: {'ok': 0.0, 'errmsg': 'Authentication failed.', 'code': 18, 'codeName': 'AuthenticationFailed'}; 695)
Traceback (most recent call last):
  File "/home/airflow/.local/lib/python3.12/site-packages/airflow/task/task_runner/standard_task_runner.py", line 117, in _start_by_fork
    ret = args.func(args, dag=self.dag)
          ^^^^^^^^^^^^^^^^^^^^^^^^^^^^^
  File "/home/airflow/.local/lib/python3.12/site-packages/airflow/cli/cli_config.py", line 49, in command
    return func(*args, **kwargs)
           ^^^^^^^^^^^^^^^^^^^^^
  File "/home/airflow/.local/lib/python3.12/site-packages/airflow/utils/cli.py", line 115, in wrapper
    return f(*args, **kwargs)
           ^^^^^^^^^^^^^^^^^^
  File "/home/airflow/.local/lib/python3.12/site-packages/airflow/cli/commands/task_command.py", line 483, in task_run
    task_return_code = _run_task_by_selected_method(args, _dag, ti)
                       ^^^^^^^^^^^^^^^^^^^^^^^^^^^^^^^^^^^^^^^^^^^^
  File "/home/airflow/.local/lib/python3.12/site-packages/airflow/cli/commands/task_command.py", line 256, in _run_task_by_selected_method
    return _run_raw_task(args, ti)
           ^^^^^^^^^^^^^^^^^^^^^^^
  File "/home/airflow/.local/lib/python3.12/site-packages/airflow/cli/commands/task_command.py", line 341, in _run_raw_task
    return ti._run_raw_task(
           ^^^^^^^^^^^^^^^^^
  File "/home/airflow/.local/lib/python3.12/site-packages/airflow/utils/session.py", line 97, in wrapper
    return func(*args, session=session, **kwargs)
           ^^^^^^^^^^^^^^^^^^^^^^^^^^^^^^^^^^^^^^
  File "/home/airflow/.local/lib/python3.12/site-packages/airflow/models/taskinstance.py", line 2995, in _run_raw_task
    return _run_raw_task(
           ^^^^^^^^^^^^^^
  File "/home/airflow/.local/lib/python3.12/site-packages/airflow/models/taskinstance.py", line 273, in _run_raw_task
    TaskInstance._execute_task_with_callbacks(
  File "/home/airflow/.local/lib/python3.12/site-packages/airflow/models/taskinstance.py", line 3149, in _execute_task_with_callbacks
    result = self._execute_task(context, task_orig)
             ^^^^^^^^^^^^^^^^^^^^^^^^^^^^^^^^^^^^^^
  File "/home/airflow/.local/lib/python3.12/site-packages/airflow/models/taskinstance.py", line 3173, in _execute_task
    return _execute_task(self, context, task_orig)
           ^^^^^^^^^^^^^^^^^^^^^^^^^^^^^^^^^^^^^^^
  File "/home/airflow/.local/lib/python3.12/site-packages/airflow/models/taskinstance.py", line 767, in _execute_task
    result = _execute_callable(context=context, **execute_callable_kwargs)
             ^^^^^^^^^^^^^^^^^^^^^^^^^^^^^^^^^^^^^^^^^^^^^^^^^^^^^^^^^^^^^
  File "/home/airflow/.local/lib/python3.12/site-packages/airflow/models/taskinstance.py", line 733, in _execute_callable
    return ExecutionCallableRunner(
           ^^^^^^^^^^^^^^^^^^^^^^^^
  File "/home/airflow/.local/lib/python3.12/site-packages/airflow/utils/operator_helpers.py", line 252, in run
    return self.func(*args, **kwargs)
           ^^^^^^^^^^^^^^^^^^^^^^^^^^
  File "/home/airflow/.local/lib/python3.12/site-packages/airflow/models/baseoperator.py", line 406, in wrapper
    return func(self, *args, **kwargs)
           ^^^^^^^^^^^^^^^^^^^^^^^^^^^
  File "/home/airflow/.local/lib/python3.12/site-packages/airflow/operators/python.py", line 238, in execute
    return_value = self.execute_callable()
                   ^^^^^^^^^^^^^^^^^^^^^^^
  File "/home/airflow/.local/lib/python3.12/site-packages/airflow/operators/python.py", line 256, in execute_callable
    return runner.run(*self.op_args, **self.op_kwargs)
           ^^^^^^^^^^^^^^^^^^^^^^^^^^^^^^^^^^^^^^^^^^^
  File "/home/airflow/.local/lib/python3.12/site-packages/airflow/utils/operator_helpers.py", line 252, in run
    return self.func(*args, **kwargs)
           ^^^^^^^^^^^^^^^^^^^^^^^^^^
  File "/opt/airflow/dags/mongodb-pipeline.py", line 16, in extract_from_mongo
    for document in documents:
                    ^^^^^^^^^
  File "/home/airflow/.local/lib/python3.12/site-packages/pymongo/cursor.py", line 1243, in next
    if len(self.__data) or self._refresh():
                           ^^^^^^^^^^^^^^^
  File "/home/airflow/.local/lib/python3.12/site-packages/pymongo/cursor.py", line 1160, in _refresh
    self.__send_message(q)
  File "/home/airflow/.local/lib/python3.12/site-packages/pymongo/cursor.py", line 1039, in __send_message
    response = client._run_operation(
               ^^^^^^^^^^^^^^^^^^^^^^
  File "/home/airflow/.local/lib/python3.12/site-packages/pymongo/_csot.py", line 108, in csot_wrapper
    return func(self, *args, **kwargs)
           ^^^^^^^^^^^^^^^^^^^^^^^^^^^
  File "/home/airflow/.local/lib/python3.12/site-packages/pymongo/mongo_client.py", line 1431, in _run_operation
    return self._retryable_read(
           ^^^^^^^^^^^^^^^^^^^^^
  File "/home/airflow/.local/lib/python3.12/site-packages/pymongo/mongo_client.py", line 1540, in _retryable_read
    return self._retry_internal(
           ^^^^^^^^^^^^^^^^^^^^^
  File "/home/airflow/.local/lib/python3.12/site-packages/pymongo/_csot.py", line 108, in csot_wrapper
    return func(self, *args, **kwargs)
           ^^^^^^^^^^^^^^^^^^^^^^^^^^^
  File "/home/airflow/.local/lib/python3.12/site-packages/pymongo/mongo_client.py", line 1507, in _retry_internal
    ).run()
      ^^^^^
  File "/home/airflow/.local/lib/python3.12/site-packages/pymongo/mongo_client.py", line 2353, in run
    return self._read() if self._is_read else self._write()
           ^^^^^^^^^^^^
  File "/home/airflow/.local/lib/python3.12/site-packages/pymongo/mongo_client.py", line 2485, in _read
    with self._client._conn_from_server(self._read_pref, self._server, self._session) as (
  File "/usr/local/lib/python3.12/contextlib.py", line 137, in __enter__
    return next(self.gen)
           ^^^^^^^^^^^^^^
  File "/home/airflow/.local/lib/python3.12/site-packages/pymongo/mongo_client.py", line 1357, in _conn_from_server
    with self._checkout(server, session) as conn:
  File "/usr/local/lib/python3.12/contextlib.py", line 137, in __enter__
    return next(self.gen)
           ^^^^^^^^^^^^^^
  File "/home/airflow/.local/lib/python3.12/site-packages/pymongo/mongo_client.py", line 1266, in _checkout
    with server.checkout(handler=err_handler) as conn:
  File "/usr/local/lib/python3.12/contextlib.py", line 137, in __enter__
    return next(self.gen)
           ^^^^^^^^^^^^^^
  File "/home/airflow/.local/lib/python3.12/site-packages/pymongo/pool.py", line 1767, in checkout
    conn = self._get_conn(checkout_started_time, handler=handler)
           ^^^^^^^^^^^^^^^^^^^^^^^^^^^^^^^^^^^^^^^^^^^^^^^^^^^^^^
  File "/home/airflow/.local/lib/python3.12/site-packages/pymongo/pool.py", line 1926, in _get_conn
    conn = self.connect(handler=handler)
           ^^^^^^^^^^^^^^^^^^^^^^^^^^^^^
  File "/home/airflow/.local/lib/python3.12/site-packages/pymongo/pool.py", line 1729, in connect
    conn.authenticate()
  File "/home/airflow/.local/lib/python3.12/site-packages/pymongo/pool.py", line 1099, in authenticate
    auth.authenticate(creds, self, reauthenticate=reauthenticate)
  File "/home/airflow/.local/lib/python3.12/site-packages/pymongo/auth.py", line 656, in authenticate
    auth_func(credentials, conn)
  File "/home/airflow/.local/lib/python3.12/site-packages/pymongo/auth.py", line 560, in _authenticate_default
    return _authenticate_scram(credentials, conn, "SCRAM-SHA-1")
           ^^^^^^^^^^^^^^^^^^^^^^^^^^^^^^^^^^^^^^^^^^^^^^^^^^^^^
  File "/home/airflow/.local/lib/python3.12/site-packages/pymongo/auth.py", line 299, in _authenticate_scram
    res = conn.command(source, cmd)
          ^^^^^^^^^^^^^^^^^^^^^^^^^
  File "/home/airflow/.local/lib/python3.12/site-packages/pymongo/helpers.py", line 342, in inner
    return func(*args, **kwargs)
           ^^^^^^^^^^^^^^^^^^^^^
  File "/home/airflow/.local/lib/python3.12/site-packages/pymongo/pool.py", line 989, in command
    return command(
           ^^^^^^^^
  File "/home/airflow/.local/lib/python3.12/site-packages/pymongo/network.py", line 212, in command
    helpers._check_command_response(
  File "/home/airflow/.local/lib/python3.12/site-packages/pymongo/helpers.py", line 248, in _check_command_response
    raise OperationFailure(errmsg, code, response, max_wire_version)
pymongo.errors.OperationFailure: Authentication failed., full error: {'ok': 0.0, 'errmsg': 'Authentication failed.', 'code': 18, 'codeName': 'AuthenticationFailed'}
[2024-09-11T02:25:16.787+0000] {local_task_job_runner.py:261} INFO - Task exited with return code 1
[2024-09-11T02:25:16.802+0000] {taskinstance.py:3891} INFO - 0 downstream tasks scheduled from follow-on schedule check
[2024-09-11T02:25:16.805+0000] {local_task_job_runner.py:240} INFO - ::endgroup::
